Workbook
Name ____LPS2: {#N/A,#N/A,FALSE,"단축1";#N/A,#N/A,FALSE,"단축2";#N/A,#N/A,FALSE,"단축3";#N/A,#N/A,FALSE,"장축";#N/A,#N/A,FALSE,"4WD"}
Name ____XG2: {#N/A,#N/A,FALSE,"단축1";#N/A,#N/A,FALSE,"단축2";#N/A,#N/A,FALSE,"단축3";#N/A,#N/A,FALSE,"장축";#N/A,#N/A,FALSE,"4WD"}
Name ___LPS2: {#N/A,#N/A,FALSE,"단축1";#N/A,#N/A,FALSE,"단축2";#N/A,#N/A,FALSE,"단축3";#N/A,#N/A,FALSE,"장축";#N/A,#N/A,FALSE,"4WD"}
Name ___XG2: {#N/A,#N/A,FALSE,"단축1";#N/A,#N/A,FALSE,"단축2";#N/A,#N/A,FALSE,"단축3";#N/A,#N/A,FALSE,"장축";#N/A,#N/A,FALSE,"4WD"}
Name __123Graph_A: [1]목표세부명세!#REF!
Name __123Graph_B: [1]목표세부명세!#REF!
Name __123Graph_C64HZ1040: #REF!
Name __123Graph_C温特図: #REF!
Name __123Graph_D64HZ1040: #REF!
Name __123Graph_F温特図: #REF!
Name __FDS_HYPERLINK_TOGGLE_STATE__: "ON"
Name __LPS2: {#N/A,#N/A,FALSE,"단축1";#N/A,#N/A,FALSE,"단축2";#N/A,#N/A,FALSE,"단축3";#N/A,#N/A,FALSE,"장축";#N/A,#N/A,FALSE,"4WD"}
Name __SDW1: '[2]#REF'!#REF!
Name __XG2: {#N/A,#N/A,FALSE,"단축1";#N/A,#N/A,FALSE,"단축2";#N/A,#N/A,FALSE,"단축3";#N/A,#N/A,FALSE,"장축";#N/A,#N/A,FALSE,"4WD"}
Name _1____S: #REF!
Name _1__0_S: #REF!
Name _10__123Graph_CI2T_T1A: #REF!
Name _12__123Graph_CI_T1A: #REF!
Name _14__123Graph_DI2T_T1A: #REF!
Name _15E1_: {#N/A,#N/A,TRUE,"매출진척-1";#N/A,#N/A,TRUE,"매출진척-2";#N/A,#N/A,TRUE,"제품실적";#N/A,#N/A,TRUE,"RAC";#N/A,#N/A,TRUE,"PAC ";#N/A,#N/A,TRUE,"재고현황";#N/A,#N/A,TRUE,"공지사항"}
Name _16__123Graph_DI_T1A: #REF!
Name _171__0_S: #REF!
Name _172__0_S: #REF!
Name _173__0_S: #REF!
Name _18__123Graph_EI2T_T1A: #REF!
Name _194_: #REF!
Name _195____S: #REF!
Name _2__123Graph_AI2T_T1A: #REF!
Name _2__0_S: #REF!
Name _20__123Graph_EI_T1A: #REF!
Name _200__0_S: #REF!
Name _201__0_S: #REF!
Name _202__0_S: #REF!
Name _203__0_S: #REF!
Name _208__0_S: #REF!
Name _209__0_S: #REF!
Name _210__0_S: #REF!
Name _22__123Graph_FI2T_T1A: #REF!
Name _23__0_S: #REF!
Name _24__123Graph_FI_T1A: #REF!
Name _24__0_S: #REF!
Name _26__123Graph_XI2T_T1A: #REF!
Name _28__123Graph_XI_T1A: #REF!
Name _2E1_: {#N/A,#N/A,TRUE,"매출진척-1";#N/A,#N/A,TRUE,"매출진척-2";#N/A,#N/A,TRUE,"제품실적";#N/A,#N/A,TRUE,"RAC";#N/A,#N/A,TRUE,"PAC ";#N/A,#N/A,TRUE,"재고현황";#N/A,#N/A,TRUE,"공지사항"}
Name _2E1_1: {#N/A,#N/A,TRUE,"매출진척-1";#N/A,#N/A,TRUE,"매출진척-2";#N/A,#N/A,TRUE,"제품실적";#N/A,#N/A,TRUE,"RAC";#N/A,#N/A,TRUE,"PAC ";#N/A,#N/A,TRUE,"재고현황";#N/A,#N/A,TRUE,"공지사항"}
Name _3__0_S: #REF!
Name _30FF2_: {#N/A,#N/A,TRUE,"매출진척-1";#N/A,#N/A,TRUE,"매출진척-2";#N/A,#N/A,TRUE,"제품실적";#N/A,#N/A,TRUE,"RAC";#N/A,#N/A,TRUE,"PAC ";#N/A,#N/A,TRUE,"재고현황";#N/A,#N/A,TRUE,"공지사항"}
Name _310__0_S: #REF!
Name _311__0_S: #REF!
Name _37__0_S: #REF!
Name _4__123Graph_AI_T1A: #REF!
Name _4__0_S: #REF!
Name _45s1_: {#N/A,#N/A,TRUE,"매출진척-1";#N/A,#N/A,TRUE,"매출진척-2";#N/A,#N/A,TRUE,"제품실적";#N/A,#N/A,TRUE,"RAC";#N/A,#N/A,TRUE,"PAC ";#N/A,#N/A,TRUE,"재고현황";#N/A,#N/A,TRUE,"공지사항"}
Name _4FF2_: {#N/A,#N/A,TRUE,"매출진척-1";#N/A,#N/A,TRUE,"매출진척-2";#N/A,#N/A,TRUE,"제품실적";#N/A,#N/A,TRUE,"RAC";#N/A,#N/A,TRUE,"PAC ";#N/A,#N/A,TRUE,"재고현황";#N/A,#N/A,TRUE,"공지사항"}
Name _5____S: #REF!
Name _6__123Graph_BI2T_T1A: #REF!
Name _69__0_S: #REF!
Name _6s1_: {#N/A,#N/A,TRUE,"매출진척-1";#N/A,#N/A,TRUE,"매출진척-2";#N/A,#N/A,TRUE,"제품실적";#N/A,#N/A,TRUE,"RAC";#N/A,#N/A,TRUE,"PAC ";#N/A,#N/A,TRUE,"재고현황";#N/A,#N/A,TRUE,"공지사항"}
Name _70__0_S: #REF!
Name _75__0_S: #REF!

Sheet Raw(1)
A1: Year | B1: Week | C1: Factory | D1: Type | E1: Category | F1: Q'ty | I1: DJ 입력일 | J1: 메일 수신일 (or 파일 작성일)
A2: 2026 | B2: 1 | C2: VN #1 | D2: Machine | E2: Growing Line | F2: 15 | H2: =_xlfn.FORMULATEXT(표1[[#This Row],[Q''ty]]) -> #N/A
A3: 2026 | B3: 1 | C3: VN #1 | D3: Machine | E3: Paint Booth | F3: 10 | H3: =_xlfn.FORMULATEXT(표1[[#This Row],[Q''ty]]) -> #N/A
A4: 2026 | B4: 1 | C4: VN #1 | D4: Machine | E4: Paint Line | F4: 5 | H4: =_xlfn.FORMULATEXT(표1[[#This Row],[Q''ty]]) -> #N/A
A5: 2026 | B5: 1 | C5: VN #1 | D5: Machine | E5: Roll Bending Machine | F5: 6 | H5: =_xlfn.FORMULATEXT(표1[[#This Row],[Q''ty]]) -> #N/A
A6: 2026 | B6: 1 | C6: VN #1 | D6: Machine | E6: L/W Machine | F6: 10 | H6: =_xlfn.FORMULATEXT(표1[[#This Row],[Q''ty]]) -> #N/A
A7: 2026 | B7: 1 | C7: VN #1 | D7: Machine | E7: C/W Machine | F7: 10 | H7: =_xlfn.FORMULATEXT(표1[[#This Row],[Q''ty]]) -> #N/A
A8: 2026 | B8: 1 | C8: VN #1 | D8: Performance | E8: BT GT | F8: 23 | H8: =_xlfn.FORMULATEXT(표1[[#This Row],[Q''ty]]) -> #N/A
A9: 2026 | B9: 1 | C9: VN #1 | D9: Performance | E9: WT GT | F9: 19 | H9: =_xlfn.FORMULATEXT(표1[[#This Row],[Q''ty]]) -> #N/A
A10: 2026 | B10: 1 | C10: VN #1 | D10: Performance | E10: Bending | F10: 217 | H10: =_xlfn.FORMULATEXT(표1[[#This Row],[Q''ty]]) -> #N/A
A11: 2026 | B11: 1 | C11: VN #1 | D11: Performance | E11: L/W | F11: 217.2 | H11: =_xlfn.FORMULATEXT(표1[[#This Row],[Q''ty]]) -> #N/A
A12: 2026 | B12: 1 | C12: VN #1 | D12: Performance | E12: C/W | F12: 244.1 | H12: =_xlfn.FORMULATEXT(표1[[#This Row],[Q''ty]]) -> #N/A
A13: 2026 | B13: 1 | C13: VN #2 | D13: Machine | E13: Growing Line | F13: 14 | H13: =_xlfn.FORMULATEXT(표1[[#This Row],[Q''ty]]) -> #N/A
... A100: 2026 | B100: 1 | C100: PT Off | D100: Performance | E100: C/W | F100: 0 | H100: =_xlfn.FORMULATEXT(표1[[#This Row],[Q''ty]]) -> #N/A
A101: 2026 | B101: =B2+1 -> 2 | C101: VN #1 | D101: Machine | E101: Growing Line | F101: =F2 -> 15 | H101: =_xlfn.FORMULATEXT(표1[[#This Row],[Q''ty]]) -> =F2
A102: 2026 | B102: =B3+1 -> 2 | C102: VN #1 | D102: Machine | E102: Paint Booth | F102: =F3 -> 10 | H102: =_xlfn.FORMULATEXT(표1[[#This Row],[Q''ty]]) -> =F3
A103: 2026 | B103: =B4+1 -> 2 | C103: VN #1 | D103: Machine | E103: Paint Line | F103: =F4 -> 5 | H103: =_xlfn.FORMULATEXT(표1[[#This Row],[Q''ty]]) -> =F4
A104: 2026 | B104: =B5+1 -> 2 | C104: VN #1 | D104: Machine | E104: Roll Bending Machine | F104: =F5 -> 6 | H104: =_xlfn.FORMULATEXT(표1[[#This Row],[Q''ty]]) -> =F5
A105: 2026 | B105: =B6+1 -> 2 | C105: VN #1 | D105: Machine | E105: L/W Machine | F105: =F6 -> 10 | H105: =_xlfn.FORMULATEXT(표1[[#This Row],[Q''ty]]) -> =F6
A106: 2026 | B106: =B7+1 -> 2 | C106: VN #1 | D106: Machine | E106: C/W Machine | F106: =F7 -> 10 | H106: =_xlfn.FORMULATEXT(표1[[#This Row],[Q''ty]]) -> =F7
A107: 2026 | B107: =B8+1 -> 2 | C107: VN #1 | D107: Performance | E107: BT GT | F107: 24 | H107: =_xlfn.FORMULATEXT(표1[[#This Row],[Q''ty]]) -> #N/A
A108: 2026 | B108: =B9+1 -> 2 | C108: VN #1 | D108: Performance | E108: WT GT | F108: 25 | H108: =_xlfn.FORMULATEXT(표1[[#This Row],[Q''ty]]) -> #N/A
A109: 2026 | B109: =B10+1 -> 2 | C109: VN #1 | D109: Performance | E109: Bending | F109: 240.4 | H109: =_xlfn.FORMULATEXT(표1[[#This Row],[Q''ty]]) -> #N/A
A110: 2026 | B110: =B11+1 -> 2 | C110: VN #1 | D110: Performance | E110: L/W | F110: 237.8 | H110: =_xlfn.FORMULATEXT(표1[[#This Row],[Q''ty]]) -> #N/A
A111: 2026 | B111: =B12+1 -> 2 | C111: VN #1 | D111: Performance | E111: C/W | F111: 264.7 | H111: =_xlfn.FORMULATEXT(표1[[#This Row],[Q''ty]]) -> #N/A
A112: 2026 | B112: =B13+1 -> 2 | C112: VN #2 | D112: Machine | E112: Growing Line | F112: =F13 -> 14 | H112: =_xlfn.FORMULATEXT(표1[[#This Row],[Q''ty]]) -> =F13
A113: 2026 | B113: =B14+1 -> 2 | C113: VN #2 | D113: Machine | E113: Paint Booth | F113: =F14 -> 8 | H113: =_xlfn.FORMULATEXT(표1[[#This Row],[Q''ty]]) -> =F14
A114: 2026 | B114: =B15+1 -> 2 | C114: VN #2 | D114: Machine | E114: Paint Line | F114: =F15 -> 4 | H114: =_xlfn.FORMULATEXT(표1[[#This Row],[Q''ty]]) -> =F15
A115: 2026 | B115: =B16+1 -> 2 | C115: VN #2 | D115: Machine | E115: Roll Bending Machine | F115: =F16 -> 3 | H115: =_xlfn.FORMULATEXT(표1[[#This Row],[Q''ty]]) -> =F16
A116: 2026 | B116: =B17+1 -> 2 | C116: VN #2 | D116: Machine | E116: L/W Machine | F116: =F17 -> 6 | H116: =_xlfn.FORMULATEXT(표1[[#This Row],[Q''ty]]) -> =F17
A117: 2026 | B117: =B18+1 -> 2 | C117: VN #2 | D117: Machine | E117: C/W Machine | F117: =F18 -> 8.8 | H117: =_xlfn.FORMULATEXT(표1[[#This Row],[Q''ty]]) -> =F18
A118: 2026 | B118: =B19+1 -> 2 | C118: VN #2 | D118: Performance | E118: BT GT | F118: 22 | H118: =_xlfn.FORMULATEXT(표1[[#This Row],[Q''ty]]) -> #N/A
A119: 2026 | B119: =B20+1 -> 2 | C119: VN #2 | D119: Performance | E119: WT GT | F119: 25 | H119: =_xlfn.FORMULATEXT(표1[[#This Row],[Q''ty]]) -> #N/A
A120: 2026 | B120: =B21+1 -> 2 | C120: VN #2 | D120: Performance | E120: Bending | F120: 179 | H120: =_xlfn.FORMULATEXT(표1[[#This Row],[Q''ty]]) -> #N/A
A121: 2026 | B121: =B22+1 -> 2 | C121: VN #2 | D121: Performance | E121: L/W | F121: 180 | H121: =_xlfn.FORMULATEXT(표1[[#This Row],[Q''ty]]) -> #N/A
A122: 2026 | B122: =B23+1 -> 2 | C122: VN #2 | D122: Performance | E122: C/W | F122: 207.7 | H122: =_xlfn.FORMULATEXT(표1[[#This Row],[Q''ty]]) -> #N/A
A123: 2026 | B123: =B24+1 -> 2 | C123: TW | D123: Machine | E123: =E24 -> Growing Line | F123: =F24 -> 5 | H123: =_xlfn.FORMULATEXT(표1[[#This Row],[Q''ty]]) -> =F24
A124: 2026 | B124: =B25+1 -> 2 | C124: TW | D124: Machine | E124: =E25 -> Paint Booth | F124: =F25 -> 3 | H124: =_xlfn.FORMULATEXT(표1[[#This Row],[Q''ty]]) -> =F25
A125: 2026 | B125: =B26+1 -> 2 | C125: TW | D125: Machine | E125: =E26 -> Paint Line | F125: =F26 -> 2 | H125: =_xlfn.FORMULATEXT(표1[[#This Row],[Q''ty]]) -> =F26
A126: 2026 | B126: =B27+1 -> 2 | C126: TW | D126: Machine | E126: =E27 -> Roll Bending Machine | F126: =F27 -> 2 | H126: =_xlfn.FORMULATEXT(표1[[#This Row],[Q''ty]]) -> =F27
...

Sheet GitHub_Export
A1: Year | B1: Week | C1: Month | D1: YearMonth | E1: Month_Sort | F1: Factory | G1: Type | H1: Category | I1: Q'ty
A2: =IF('Raw(1)'!A2="","",'Raw(1)'!A2) -> 2026 | B2: =IF('Raw(1)'!B2="","",'Raw(1)'!B2) -> 1 | C2: =IF(OR(A2="",B2=""),"",TEXT(DATE(A2,1,1)+(B2-1)*7,"mmm")) -> Jan | D2: =IF(OR(A2="",B2=""),"",TEXT(DATE(A2,1,1)+(B2-1)*7,"yyyy-mmm")) -> 2026-Jan | E2: =IF(OR(A2="",B2=""),"",YEAR(DATE(A2,1,1)+(B2-1)*7)*100+MONTH(DATE(A2,1,1)+(B2-1)*7)) -> 202601 | F2: =IF('Raw(1)'!C2="","",'Raw(1)'!C2) -> VN #1 | G2: =IF('Raw(1)'!D2="","",'Raw(1)'!D2) -> Machine | H2: =IF('Raw(1)'!E2="","",'Raw(1)'!E2) -> Growing Line | I2: =IF('Raw(1)'!F2="","",'Raw(1)'!F2) -> 15
A3: =IF('Raw(1)'!A3="","",'Raw(1)'!A3) -> 2026 | B3: =IF('Raw(1)'!B3="","",'Raw(1)'!B3) -> 1 | C3: =IF(OR(A3="",B3=""),"",TEXT(DATE(A3,1,1)+(B3-1)*7,"mmm")) -> Jan | D3: =IF(OR(A3="",B3=""),"",TEXT(DATE(A3,1,1)+(B3-1)*7,"yyyy-mmm")) -> 2026-Jan | E3: =IF(OR(A3="",B3=""),"",YEAR(DATE(A3,1,1)+(B3-1)*7)*100+MONTH(DATE(A3,1,1)+(B3-1)*7)) -> 202601 | F3: =IF('Raw(1)'!C3="","",'Raw(1)'!C3) -> VN #1 | G3: =IF('Raw(1)'!D3="","",'Raw(1)'!D3) -> Machine | H3: =IF('Raw(1)'!E3="","",'Raw(1)'!E3) -> Paint Booth | I3: =IF('Raw(1)'!F3="","",'Raw(1)'!F3) -> 10
A4: =IF('Raw(1)'!A4="","",'Raw(1)'!A4) -> 2026 | B4: =IF('Raw(1)'!B4="","",'Raw(1)'!B4) -> 1 | C4: =IF(OR(A4="",B4=""),"",TEXT(DATE(A4,1,1)+(B4-1)*7,"mmm")) -> Jan | D4: =IF(OR(A4="",B4=""),"",TEXT(DATE(A4,1,1)+(B4-1)*7,"yyyy-mmm")) -> 2026-Jan | E4: =IF(OR(A4="",B4=""),"",YEAR(DATE(A4,1,1)+(B4-1)*7)*100+MONTH(DATE(A4,1,1)+(B4-1)*7)) -> 202601 | F4: =IF('Raw(1)'!C4="","",'Raw(1)'!C4) -> VN #1 | G4: =IF('Raw(1)'!D4="","",'Raw(1)'!D4) -> Machine | H4: =IF('Raw(1)'!E4="","",'Raw(1)'!E4) -> Paint Line | I4: =IF('Raw(1)'!F4="","",'Raw(1)'!F4) -> 5
A5: =IF('Raw(1)'!A5="","",'Raw(1)'!A5) -> 2026 | B5: =IF('Raw(1)'!B5="","",'Raw(1)'!B5) -> 1 | C5: =IF(OR(A5="",B5=""),"",TEXT(DATE(A5,1,1)+(B5-1)*7,"mmm")) -> Jan | D5: =IF(OR(A5="",B5=""),"",TEXT(DATE(A5,1,1)+(B5-1)*7,"yyyy-mmm")) -> 2026-Jan | E5: =IF(OR(A5="",B5=""),"",YEAR(DATE(A5,1,1)+(B5-1)*7)*100+MONTH(DATE(A5,1,1)+(B5-1)*7)) -> 202601 | F5: =IF('Raw(1)'!C5="","",'Raw(1)'!C5) -> VN #1 | G5: =IF('Raw(1)'!D5="","",'Raw(1)'!D5) -> Machine | H5: =IF('Raw(1)'!E5="","",'Raw(1)'!E5) -> Roll Bending Machine | I5: =IF('Raw(1)'!F5="","",'Raw(1)'!F5) -> 6
A6: =IF('Raw(1)'!A6="","",'Raw(1)'!A6) -> 2026 | B6: =IF('Raw(1)'!B6="","",'Raw(1)'!B6) -> 1 | C6: =IF(OR(A6="",B6=""),"",TEXT(DATE(A6,1,1)+(B6-1)*7,"mmm")) -> Jan | D6: =IF(OR(A6="",B6=""),"",TEXT(DATE(A6,1,1)+(B6-1)*7,"yyyy-mmm")) -> 2026-Jan | E6: =IF(OR(A6="",B6=""),"",YEAR(DATE(A6,1,1)+(B6-1)*7)*100+MONTH(DATE(A6,1,1)+(B6-1)*7)) -> 202601 | F6: =IF('Raw(1)'!C6="","",'Raw(1)'!C6) -> VN #1 | G6: =IF('Raw(1)'!D6="","",'Raw(1)'!D6) -> Machine | H6: =IF('Raw(1)'!E6="","",'Raw(1)'!E6) -> L/W Machine | I6: =IF('Raw(1)'!F6="","",'Raw(1)'!F6) -> 10
A7: =IF('Raw(1)'!A7="","",'Raw(1)'!A7) -> 2026 | B7: =IF('Raw(1)'!B7="","",'Raw(1)'!B7) -> 1 | C7: =IF(OR(A7="",B7=""),"",TEXT(DATE(A7,1,1)+(B7-1)*7,"mmm")) -> Jan | D7: =IF(OR(A7="",B7=""),"",TEXT(DATE(A7,1,1)+(B7-1)*7,"yyyy-mmm")) -> 2026-Jan | E7: =IF(OR(A7="",B7=""),"",YEAR(DATE(A7,1,1)+(B7-1)*7)*100+MONTH(DATE(A7,1,1)+(B7-1)*7)) -> 202601 | F7: =IF('Raw(1)'!C7="","",'Raw(1)'!C7) -> VN #1 | G7: =IF('Raw(1)'!D7="","",'Raw(1)'!D7) -> Machine | H7: =IF('Raw(1)'!E7="","",'Raw(1)'!E7) -> C/W Machine | I7: =IF('Raw(1)'!F7="","",'Raw(1)'!F7) -> 10
A8: =IF('Raw(1)'!A8="","",'Raw(1)'!A8) -> 2026 | B8: =IF('Raw(1)'!B8="","",'Raw(1)'!B8) -> 1 | C8: =IF(OR(A8="",B8=""),"",TEXT(DATE(A8,1,1)+(B8-1)*7,"mmm")) -> Jan | D8: =IF(OR(A8="",B8=""),"",TEXT(DATE(A8,1,1)+(B8-1)*7,"yyyy-mmm")) -> 2026-Jan | E8: =IF(OR(A8="",B8=""),"",YEAR(DATE(A8,1,1)+(B8-1)*7)*100+MONTH(DATE(A8,1,1)+(B8-1)*7)) -> 202601 | F8: =IF('Raw(1)'!C8="","",'Raw(1)'!C8) -> VN #1 | G8: =IF('Raw(1)'!D8="","",'Raw(1)'!D8) -> Performance | H8: =IF('Raw(1)'!E8="","",'Raw(1)'!E8) -> BT GT | I8: =IF('Raw(1)'!F8="","",'Raw(1)'!F8) -> 23
A9: =IF('Raw(1)'!A9="","",'Raw(1)'!A9) -> 2026 | B9: =IF('Raw(1)'!B9="","",'Raw(1)'!B9) -> 1 | C9: =IF(OR(A9="",B9=""),"",TEXT(DATE(A9,1,1)+(B9-1)*7,"mmm")) -> Jan | D9: =IF(OR(A9="",B9=""),"",TEXT(DATE(A9,1,1)+(B9-1)*7,"yyyy-mmm")) -> 2026-Jan | E9: =IF(OR(A9="",B9=""),"",YEAR(DATE(A9,1,1)+(B9-1)*7)*100+MONTH(DATE(A9,1,1)+(B9-1)*7)) -> 202601 | F9: =IF('Raw(1)'!C9="","",'Raw(1)'!C9) -> VN #1 | G9: =IF('Raw(1)'!D9="","",'Raw(1)'!D9) -> Performance | H9: =IF('Raw(1)'!E9="","",'Raw(1)'!E9) -> WT GT | I9: =IF('Raw(1)'!F9="","",'Raw(1)'!F9) -> 19
A10: =IF('Raw(1)'!A10="","",'Raw(1)'!A10) -> 2026 | B10: =IF('Raw(1)'!B10="","",'Raw(1)'!B10) -> 1 | C10: =IF(OR(A10="",B10=""),"",TEXT(DATE(A10,1,1)+(B10-1)*7,"mmm")) -> Jan | D10: =IF(OR(A10="",B10=""),"",TEXT(DATE(A10,1,1)+(B10-1)*7,"yyyy-mmm")) -> 2026-Jan | E10: =IF(OR(A10="",B10=""),"",YEAR(DATE(A10,1,1)+(B10-1)*7)*100+MONTH(DATE(A10,1,1)+(B10-1)*7)) -> 202601 | F10: =IF('Raw(1)'!C10="","",'Raw(1)'!C10) -> VN #1 | G10: =IF('Raw(1)'!D10="","",'Raw(1)'!D10) -> Performance | H10: =IF('Raw(1)'!E10="","",'Raw(1)'!E10) -> Bending | I10: =IF('Raw(1)'!F10="","",'Raw(1)'!F10) -> 217
A11: =IF('Raw(1)'!A11="","",'Raw(1)'!A11) -> 2026 | B11: =IF('Raw(1)'!B11="","",'Raw(1)'!B11) -> 1 | C11: =IF(OR(A11="",B11=""),"",TEXT(DATE(A11,1,1)+(B11-1)*7,"mmm")) -> Jan | D11: =IF(OR(A11="",B11=""),"",TEXT(DATE(A11,1,1)+(B11-1)*7,"yyyy-mmm")) -> 2026-Jan | E11: =IF(OR(A11="",B11=""),"",YEAR(DATE(A11,1,1)+(B11-1)*7)*100+MONTH(DATE(A11,1,1)+(B11-1)*7)) -> 202601 | F11: =IF('Raw(1)'!C11="","",'Raw(1)'!C11) -> VN #1 | G11: =IF('Raw(1)'!D11="","",'Raw(1)'!D11) -> Performance | H11: =IF('Raw(1)'!E11="","",'Raw(1)'!E11) -> L/W | I11: =IF('Raw(1)'!F11="","",'Raw(1)'!F11) -> 217.2
A12: =IF('Raw(1)'!A12="","",'Raw(1)'!A12) -> 2026 | B12: =IF('Raw(1)'!B12="","",'Raw(1)'!B12) -> 1 | C12: =IF(OR(A12="",B12=""),"",TEXT(DATE(A12,1,1)+(B12-1)*7,"mmm")) -> Jan | D12: =IF(OR(A12="",B12=""),"",TEXT(DATE(A12,1,1)+(B12-1)*7,"yyyy-mmm")) -> 2026-Jan | E12: =IF(OR(A12="",B12=""),"",YEAR(DATE(A12,1,1)+(B12-1)*7)*100+MONTH(DATE(A12,1,1)+(B12-1)*7)) -> 202601 | F12: =IF('Raw(1)'!C12="","",'Raw(1)'!C12) -> VN #1 | G12: =IF('Raw(1)'!D12="","",'Raw(1)'!D12) -> Performance | H12: =IF('Raw(1)'!E12="","",'Raw(1)'!E12) -> C/W | I12: =IF('Raw(1)'!F12="","",'Raw(1)'!F12) -> 244.1
A13: =IF('Raw(1)'!A13="","",'Raw(1)'!A13) -> 2026 | B13: =IF('Raw(1)'!B13="","",'Raw(1)'!B13) -> 1 | C13: =IF(OR(A13="",B13=""),"",TEXT(DATE(A13,1,1)+(B13-1)*7,"mmm")) -> Jan | D13: =IF(OR(A13="",B13=""),"",TEXT(DATE(A13,1,1)+(B13-1)*7,"yyyy-mmm")) -> 2026-Jan | E13: =IF(OR(A13="",B13=""),"",YEAR(DATE(A13,1,1)+(B13-1)*7)*100+MONTH(DATE(A13,1,1)+(B13-1)*7)) -> 202601 | F13: =IF('Raw(1)'!C13="","",'Raw(1)'!C13) -> VN #2 | G13: =IF('Raw(1)'!D13="","",'Raw(1)'!D13) -> Machine | H13: =IF('Raw(1)'!E13="","",'Raw(1)'!E13) -> Growing Line | I13: =IF('Raw(1)'!F13="","",'Raw(1)'!F13) -> 14
... A5248: =IF('Raw(1)'!A5248="","",'Raw(1)'!A5248) -> 2026 | B5248: =IF('Raw(1)'!B5248="","",'Raw(1)'!B5248) -> 53 | C5248: =IF(OR(A5248="",B5248=""),"",TEXT(DATE(A5248,1,1)+(B5248-1)*7,"mmm")) -> Dec | D5248: =IF(OR(A5248="",B5248=""),"",TEXT(DATE(A5248,1,1)+(B5248-1)*7,"yyyy-mmm")) -> 2026-Dec | E5248: =IF(OR(A5248="",B5248=""),"",YEAR(DATE(A5248,1,1)+(B5248-1)*7)*100+MONTH(DATE(A5248,1,1)+(B5248-1)*7)) -> 202612 | F5248: =IF('Raw(1)'!C5248="","",'Raw(1)'!C5248) -> PT Off | G5248: =IF('Raw(1)'!D5248="","",'Raw(1)'!D5248) -> Performance | H5248: =IF('Raw(1)'!E5248="","",'Raw(1)'!E5248) -> C/W | I5248: =IF('Raw(1)'!F5248="","",'Raw(1)'!F5248)

Sheet README_GitHub
A1: GitHub Upload Guide
A3: 1) Raw(1) 시트는 원본으로 유지합니다.
A4: 2) GitHub_Export 시트는 Raw(1)을 링크 수식으로 참조합니다.
A5: 3) GitHub 업로드 전 Excel에서 Ctrl+Alt+Shift+F9 → 저장 후 업로드하세요.
A6: 4) GitHub의 scripts/convert_excel.py는 GitHub_Export 시트를 우선 읽도록 교체하세요.
